<?xml version='1.0'?>
<sdf version='1.7'>
  <model name='ur5_rg2'>
    <model name='ur5_rg2'>
      <joint name='ur5_rg2_joint_world' type='fixed'>
        <parent>world</parent>
        <child>base_link</child>
      </joint>
      <link name='base_link'>
        <visual name='base_link_visual'>
          <geometry>
            <mesh>
              <uri>meshes/visual/ur5/base.dae</uri>
            </mesh>
          </geometry>
        </visual>
        <collision name='base_link_collision'>
          <geometry>
            <mesh>
              <uri>meshes/collision/ur5/base.stl</uri>
            </mesh>
          </geometry>
          <surface>
            <friction>
              <ode>
                <mu>1.2</mu>
                <mu2>1.2</mu2>
              </ode>
            </friction>
          </surface>
        </collision>
        <inertial>
          <pose>-1e-06 0.004422 0.184343 0 -0 0</pose>
          <mass>4.21039</mass>
          <inertia>
            <ixx>0.0930967</ixx>
            <iyy>0.0925704</iyy>
            <izz>0.00431065</izz>
            <ixy>5.71127e-09</ixy>
            <ixz>2.00398e-07</ixz>
            <iyz>0.00470535</iyz>
          </inertia>
        </inertial>
      </link>
      <link name='shoulder_link'>
        <pose>0 0 0.089159 0 -0 0</pose>
        <visual name='shoulder_link_visual'>
          <geometry>
            <mesh>
              <uri>meshes/visual/ur5/shoulder.dae</uri>
            </mesh>
          </geometry>
        </visual>
        <collision name='shoulder_link_collision'>
          <geometry>
            <mesh>
              <uri>meshes/collision/ur5/shoulder.stl</uri>
            </mesh>
          </geometry>
          <surface>
            <friction>
              <ode>
                <mu>1.2</mu>
                <mu2>1.2</mu2>
              </ode>
            </friction>
          </surface>
        </collision>
        <inertial>
          <pose>-4e-06 0.009273 -0.001856 0 -0 0</pose>
          <mass>2.60786</mass>
          <inertia>
            <ixx>0.00615891</ixx>
            <iyy>0.00556293</iyy>
            <izz>0.00525508</izz>
            <ixy>8.48668e-07</ixy>
            <ixz>1.43603e-07</ixz>
            <iyz>-0.0001881</iyz>
          </inertia>
        </inertial>
      </link>
      <link name='upper_arm_link'>
        <pose>0 0.13585 0.089159 0 -0 0</pose>
        <visual name='upper_arm_link_visual'>
          <geometry>
            <mesh>
              <uri>meshes/visual/ur5/upperarm.dae</uri>
            </mesh>
          </geometry>
        </visual>
        <collision name='upper_arm_link_collision'>
          <geometry>
            <mesh>
              <uri>meshes/collision/ur5/upperarm.stl</uri>
            </mesh>
          </geometry>
          <surface>
            <friction>
              <ode>
                <mu>1.2</mu>
                <mu2>1.2</mu2>
              </ode>
            </friction>
          </surface>
        </collision>
        <inertial>
          <pose>0 -0.001072 0.2125 0 -0 0</pose>
          <mass>9.03456</mass>
          <inertia>
            <ixx>0.256654</ixx>
            <iyy>0.254839</iyy>
            <izz>0.0160223</izz>
            <ixy>-2.21735e-09</ixy>
            <ixz>2.33977e-06</ixz>
            <iyz>5.7019e-09</iyz>
          </inertia>
        </inertial>
      </link>
      <link name='forearm_link'>
        <pose>0 0.01615 0.514159 0 -0 0</pose>
        <visual name='forearm_link_visual'>
          <geometry>
            <mesh>
              <uri>meshes/visual/ur5/forearm.dae</uri>
            </mesh>
          </geometry>
        </visual>
        <collision name='forearm_link_collision'>
          <geometry>
            <mesh>
              <uri>meshes/collision/ur5/forearm.stl</uri>
            </mesh>
          </geometry>
          <surface>
            <friction>
              <ode>
                <mu>1.2</mu>
                <mu2>1.2</mu2>
              </ode>
            </friction>
          </surface>
        </collision>
        <inertial>
          <pose>-1e-06 0.004422 0.184343 0 -0 0</pose>
          <mass>4.21039</mass>
          <inertia>
            <ixx>0.0930967</ixx>
            <iyy>0.0925704</iyy>
            <izz>0.00431065</izz>
            <ixy>5.71127e-09</ixy>
            <ixz>2.00398e-07</ixz>
            <iyz>0.00470535</iyz>
          </inertia>
        </inertial>
      </link>
      <link name='wrist_1_link'>
        <pose>0 0.01615 0.906409 0 -0 0</pose>
        <visual name='wrist_1_link_visual'>
          <geometry>
            <mesh>
              <uri>meshes/visual/ur5/wrist1.dae</uri>
            </mesh>
          </geometry>
        </visual>
        <collision name='wrist_1_link_collision'>
          <geometry>
            <mesh>
              <uri>meshes/collision/ur5/wrist1.stl</uri>
            </mesh>
          </geometry>
          <surface>
            <friction>
              <ode>
                <mu>1.2</mu>
                <mu2>1.2</mu2>
              </ode>
            </friction>
          </surface>
        </collision>
        <inertial>
          <pose>2e-06 0.088624 -0.003577 0 -0 0</pose>
          <mass>0.865278</mass>
          <inertia>
            <ixx>0.00110067</ixx>
            <iyy>0.00102466</iyy>
            <izz>0.000712521</izz>
            <ixy>-4.06206e-08</ixy>
            <ixz>-2.44113e-08</ixz>
            <iyz>1.00092e-05</iyz>
          </inertia>
        </inertial>
      </link>
      <link name='wrist_2_link'>
        <pose>0 0.10915 0.906409 0 -0 0</pose>
        <visual name='wrist_2_link_visual'>
          <geometry>
            <mesh>
              <uri>meshes/visual/ur5/wrist2.dae</uri>
            </mesh>
          </geometry>
        </visual>
        <collision name='wrist_2_link_collision'>
          <geometry>
            <mesh>
              <uri>meshes/collision/ur5/wrist2.stl</uri>
            </mesh>
          </geometry>
          <surface>
            <friction>
              <ode>
                <mu>1.2</mu>
                <mu2>1.2</mu2>
              </ode>
            </friction>
          </surface>
        </collision>
        <inertial>
          <pose>-2e-06 -0.003577 0.090105 0 -0 0</pose>
          <mass>0.865279</mass>
          <inertia>
            <ixx>0.00109809</ixx>
            <iyy>0.000709938</iyy>
            <izz>0.00102466</izz>
            <ixy>2.43603e-08</ixy>
            <ixz>4.04709e-08</ixz>
            <iyz>4.96085e-06</iyz>
          </inertia>
        </inertial>
      </link>
      <link name='wrist_3_link'>
        <pose>0 0.10915 1.00106 0 -0 0</pose>
        <visual name='wrist_3_link_visual'>
          <geometry>
            <mesh>
              <uri>meshes/visual/ur5/wrist3.dae</uri>
            </mesh>
          </geometry>
        </visual>
        <collision name='wrist_3_link_collision'>
          <geometry>
            <mesh>
              <uri>meshes/collision/ur5/wrist3.stl</uri>
            </mesh>
          </geometry>
          <surface>
            <friction>
              <ode>
                <mu>1.2</mu>
                <mu2>1.2</mu2>
              </ode>
            </friction>
          </surface>
        </collision>
        <inertial>
          <pose>0 0.063091 0.00019 0 -0 0</pose>
          <mass>0.23286</mass>
          <inertia>
            <ixx>0.000100685</ixx>
            <iyy>0.000160164</iyy>
            <izz>9.9512e-05</izz>
            <ixy>-1.31954e-11</ixy>
            <ixz>2.04667e-11</ixz>
            <iyz>3.42145e-08</iyz>
          </inertia>
        </inertial>
      </link>
      <joint name='shoulder_pan_joint' type='revolute'>
        <pose>0 0 0 0 -0 0</pose>
        <parent>base_link</parent>
        <child>shoulder_link</child>
        <axis>
          <xyz>0 0 1</xyz>
          <limit>
            <effort>150</effort>
            <lower>-6.28319</lower>
            <upper>6.28319</upper>
            <velocity>3.15</velocity>
          </limit>
          <dynamics>
            <spring_reference>0</spring_reference>
            <spring_stiffness>0</spring_stiffness>
            <damping>30</damping>
            <friction>4</friction>
          </dynamics>
        </axis>
      </joint>
      <joint name='shoulder_lift_joint' type='revolute'>
        <pose>0 0 0 0 -0 0</pose>
        <parent>shoulder_link</parent>
        <child>upper_arm_link</child>
        <axis>
          <xyz>0 1 0</xyz>
          <limit>
            <effort>150</effort>
            <lower>-6.28319</lower>
            <upper>6.28319</upper>
            <velocity>3.15</velocity>
          </limit>
          <dynamics>
            <spring_reference>0</spring_reference>
            <spring_stiffness>0</spring_stiffness>
            <damping>45</damping>
            <friction>6</friction>
          </dynamics>
        </axis>
      </joint>
      <joint name='elbow_joint' type='revolute'>
        <pose>0 0 -0 0 -0 0</pose>
        <parent>upper_arm_link</parent>
        <child>forearm_link</child>
        <axis>
          <xyz>0 1 0</xyz>
          <limit>
            <effort>150</effort>
            <lower>-6.28319</lower>
            <upper>6.28319</upper>
            <velocity>3.15</velocity>
          </limit>
          <dynamics>
            <spring_reference>0</spring_reference>
            <spring_stiffness>0</spring_stiffness>
            <damping>35</damping>
            <friction>5</friction>
          </dynamics>
        </axis>
      </joint>
      <joint name='wrist_1_joint' type='revolute'>
        <pose>0 0 0 0 -0 0</pose>
        <parent>forearm_link</parent>
        <child>wrist_1_link</child>
        <axis>
          <xyz>0 1 0</xyz>
          <limit>
            <effort>28</effort>
            <lower>-6.28319</lower>
            <upper>6.28319</upper>
            <velocity>3.2</velocity>
          </limit>
          <dynamics>
            <spring_reference>0</spring_reference>
            <spring_stiffness>0</spring_stiffness>
            <damping>25</damping>
            <friction>3.5</friction>
          </dynamics>
        </axis>
      </joint>
      <joint name='wrist_2_joint' type='revolute'>
        <pose>0 0 0 0 -0 0</pose>
        <parent>wrist_1_link</parent>
        <child>wrist_2_link</child>
        <axis>
          <xyz>0 0 1</xyz>
          <limit>
            <effort>28</effort>
            <lower>-6.28319</lower>
            <upper>6.28319</upper>
            <velocity>3.2</velocity>
          </limit>
          <dynamics>
            <spring_reference>0</spring_reference>
            <spring_stiffness>0</spring_stiffness>
            <damping>20</damping>
            <friction>2.5</friction>
          </dynamics>
        </axis>
      </joint>
      <joint name='wrist_3_joint' type='revolute'>
        <pose>0 0 0 0 -0 0</pose>
        <parent>wrist_2_link</parent>
        <child>wrist_3_link</child>
        <axis>
          <xyz>0 1 0</xyz>
          <limit>
            <effort>28</effort>
            <lower>-6.28319</lower>
            <upper>6.28319</upper>
            <velocity>3.2</velocity>
          </limit>
          <dynamics>
            <spring_reference>0</spring_reference>
            <spring_stiffness>0</spring_stiffness>
            <damping>15</damping>
            <friction>1.75</friction>
          </dynamics>
        </axis>
      </joint>
      <joint name='ur5_hand_joint' type='fixed'>
        <pose>0 0 0 0 -0 0</pose>
        <parent>wrist_3_link</parent>
        <child>rg2_hand</child>
      </joint>
      <link name='rg2_hand'>
        <pose>0 0.19145 1.00106 1.5708 -0 1.5708</pose>
        <visual name='rg2_hand_visual'>
          <pose>0 0 0 0 -0 0</pose>
          <geometry>
            <mesh>
              <uri>meshes/visual/rg2/hand.dae</uri>
            </mesh>
          </geometry>
        </visual>
        <collision name='rg2_hand_collision'>
          <pose>0 0 0 0 -0 0</pose>
          <geometry>
            <mesh>
              <uri>meshes/collision/rg2/hand.stl</uri>
            </mesh>
          </geometry>
          <surface>
            <friction>
              <ode>
                <mu>1.2</mu>
                <mu2>1.2</mu2>
              </ode>
            </friction>
          </surface>
        </collision>
        <inertial>
          <pose>0.057581 -0.000169 -3.3e-05 0 -0 0</pose>
          <mass>0.298815</mass>
          <inertia>
            <ixx>0.000109343</ixx>
            <iyy>0.000332757</iyy>
            <izz>0.00037339</izz>
            <ixy>2.42971e-07</ixy>
            <ixz>5.39589e-08</ixz>
            <iyz>2.48999e-07</iyz>
          </inertia>
        </inertial>
      </link>
      <link name='rg2_leftfinger'>
        <pose>0 0.29645 1.01806 1.5708 -0 1.5708</pose>
        <visual name='rg2_leftfinger_visual'>
          <geometry>
            <mesh>
              <uri>meshes/visual/rg2/finger.dae</uri>
            </mesh>
          </geometry>
        </visual>
        <collision name='rg2_leftfinger_collision'>
          <geometry>
            <mesh>
              <uri>meshes/collision/rg2/finger.stl</uri>
            </mesh>
          </geometry>
          <surface>
            <friction>
              <ode>
                <mu>2.15</mu>
                <mu2>2.15</mu2>
              </ode>
            </friction>
          </surface>
        </collision>
        <inertial>
          <pose>-0.017687 -0.008191 -4.2e-05 0 -0 0</pose>
          <mass>0.240593</mass>
          <inertia>
            <ixx>3.39709e-05</ixx>
            <iyy>0.000292305</iyy>
            <izz>0.000309174</izz>
            <ixy>-4.88546e-05</ixy>
            <ixz>-1.17659e-08</ixz>
            <iyz>1.63507e-08</iyz>
          </inertia>
        </inertial>
      </link>
      <link name='rg2_rightfinger'>
        <pose>0 0.29645 0.984059 1.5708 -0 1.5708</pose>
        <visual name='rg2_rightfinger_visual'>
          <pose>0 0 0 3.14159 -0 0</pose>
          <geometry>
            <mesh>
              <uri>meshes/visual/rg2/finger.dae</uri>
            </mesh>
          </geometry>
        </visual>
        <collision name='rg2_rightfinger_collision'>
          <pose>0 0 0 3.14159 -0 0</pose>
          <geometry>
            <mesh>
              <uri>meshes/collision/rg2/finger.stl</uri>
            </mesh>
          </geometry>
          <surface>
            <friction>
              <ode>
                <mu>2.15</mu>
                <mu2>2.15</mu2>
              </ode>
            </friction>
          </surface>
        </collision>
        <inertial>
          <pose>-0.017687 -0.008191 -4.2e-05 3.14159 -0 0</pose>
          <mass>0.240593</mass>
          <inertia>
            <ixx>3.39709e-05</ixx>
            <iyy>0.000292305</iyy>
            <izz>0.000309174</izz>
            <ixy>-4.88546e-05</ixy>
            <ixz>-1.17659e-08</ixz>
            <iyz>1.63507e-08</iyz>
          </inertia>
        </inertial>
      </link>
      <joint name='rg2_finger_joint1' type='revolute'>
        <pose>0 -0 -0 0 -0 0</pose>
        <parent>rg2_hand</parent>
        <child>rg2_leftfinger</child>
        <axis>
          <xyz>0 0 1</xyz>
          <limit>
            <effort>10.6</effort>
            <lower>0</lower>
            <upper>1.18</upper>
            <velocity>1.57</velocity>
          </limit>
          <dynamics>
            <spring_reference>0</spring_reference>
            <spring_stiffness>0</spring_stiffness>
            <damping>1</damping>
            <friction>0.005</friction>
          </dynamics>
        </axis>
      </joint>
      <joint name='rg2_finger_joint2' type='revolute'>
        <pose>0 -0 -0 0 -0 0</pose>
        <parent>rg2_hand</parent>
        <child>rg2_rightfinger</child>
        <axis>
          <xyz>0 0 -1</xyz>
          <limit>
            <effort>10.6</effort>
            <lower>0</lower>
            <upper>1.18</upper>
            <velocity>1.57</velocity>
          </limit>
          <dynamics>
            <spring_reference>0</spring_reference>
            <spring_stiffness>0</spring_stiffness>
            <damping>1</damping>
            <friction>0.005</friction>
          </dynamics>
        </axis>
      </joint>
      <link name='tool0'>
        <pose>0 0.38415 1.00106 -1.5708 0 0</pose>
      </link>
      <joint name='joint1' type='fixed'>
        <pose>0 0 0 0 -0 0</pose>
        <parent>wrist_3_link</parent>
        <child>tool0</child>
      </joint>
      <pose>2.0616 -5.69709 0 0 -0 0</pose>
    </model>
    <static>0</static>
    <allow_auto_disable>1</allow_auto_disable>
  </model>
</sdf>
